Workbook

Sheet English
A1: Number | B1: Link | C1: Title | D1: Title (Hebrew) | E1: Description | F1: Description (Hebrew) | G1: published Date | H1: Event date from | I1: Event date to | J1: Platform | K1: Author | L1: Author (Hebrew) | M1: Source | N1: Reference | O1: Language | P1: Location | Q1: Location (Hebrew) | R1: Type | S1: Media | T1: Theme (tag) | U1: Places & Organizations (tag) | V1: Locations (tag) | W1: Figures (tag)
A2: 2384 | B2: https://www.undp.org/press-releases/new-un-report-impacts-war-have-set-back-development-gaza-much-69-years | C2: UNDP Report says development in Gaza went back by 69 years | D2: =VLOOKUP($A2,Hebrew!$A:$S,3,0) -> דו"ח חדש של UNDP אומר שחלה נסיגה של כ-69 שנים בהתפתחות עזה | E2: A new UN report highlights the severe impacts of war on Gaza's development, projecting a rise in poverty and a significant contraction in GDP and employment in the State of Palestine. | F2: =VLOOKUP($A2,Hebrew!$A:$S,4,0) -> דו"ח חדש מטעם ארגון הפיתוח של האו"ם קובעת שבלי הסרת המגבלות הכלכליות ואפשרות שיקום והשקעות בפיתוח, צפויה עלייה בעוני, צמצום בתמ"ג וברמת התעסוקה בכלכלה הפלסטינית | G2: October 22, 2024 | J2: UNDP (UN Development Programme) | K2: United Nations Development Programme | L2: =VLOOKUP($A2,Hebrew!$A:$S,9,0) -> תכנית הפיתוח של האו"ם (UNPD) | N2: https://www.undp.org/arab-states/publications/gaza-war-expected-socio-economic-impacts-state-palestine-october-2024 | O2: English | P2: Gaza Strip | Q2: =VLOOKUP($A2,Hebrew!$A:$S,13,0) -> רצועת עזה | R2: Official Report | S2: Text | T2: Economy, Humanitarian Aid, Blockade, Reconstruction | V2: Gaza Strip
A3: 2385 | B3: https://www.haaretz.co.il/opinions/2024-12-22/ty-article-opinion/.premium/00000193-ea47-d35c-a79f-fae7bf390000 | C3: Brigadier General Vach's Worldview is Known. Nonetheless, He was Charged with Commanding a Sensitive Area | D3: =VLOOKUP(A3,Hebrew!A:C,3,0) -> השקפת העולם של תא"ל ואך ידועה. למרות זאת הופקד על גזרה רגישה בעזה | E3: The opinion piece discusses the military actions in Gaza and the controversial decisions made by Brigadier General Yehuda Vach, despite the sensitivity of the situation. | F3: =VLOOKUP($A3,Hebrew!$A:$S,4,0) -> מאמר הדעה דן בפעילות הצבא ברצועת עזה וחילוקי הדעות סביב החלטות תא"ל וואך, למרות רגישות המצב | G3: December 22, 2024 | H3: August 7, 2024 | J3: Haaretz | K3: Yagil Levi | L3: =VLOOKUP($A3,Hebrew!$A:$S,9,0) -> יגיל לוי | N3: https://www.haaretz.co.il/news/magazine/2024-12-18/ty-article-magazine/.premium/00000193-d01a-dcf9-afbb-deff388f0000 | O3: Hebrew | P3: Netzarim Corridor | Q3: =VLOOKUP($A3,Hebrew!$A:$S,13,0) -> מסדרון נצרים | R3: Opinion | S3: Text | T3: Ethnic Cleansing, Rules of Engagement, Religious Right | U3: IDF (Israel Defense Forces) | V3: Netzarim Corridor
A4: 2386 | B4: https://reliefweb.int/report/occupied-palestinian-territory/israels-assault-foundations-international-law-must-have-consequences-un-experts | C4: UN: Israel must have consequnces for attacking humanitarian law | D4: =VLOOKUP(A4,Hebrew!A:C,3,0) -> האו"ם: על ישראל לשאת בשלכות של הפרת הדין הבינלאומי | E4: UN experts condemn Israel's violations of international law in the occupied Palestinian territory and call for accountability for crimes against humanity and war crimes. | F4: =VLOOKUP($A4,Hebrew!$A:$S,4,0) -> מומחי האו"ם מאשימים את ישראל בהפרת החוק הבינלאומי בשטחים הפלסטינים הכבושים וקוראים להכרה בפשעים נגד האנושות ופשעי מלחמה. | G4: December 30, 2024 | J4: ReliefWeb | K4: ReliefWeb | L4: =VLOOKUP($A4,Hebrew!$A:$S,9,0) -> ReliefWeb | N4: https://www.ohchr.org/en/press-releases/2024/12/israels-assault-foundations-international-law-must-have-consequences-un?sub-site=HRC | O4: English | P4: Gaza Strip | Q4: =VLOOKUP($A4,Hebrew!$A:$S,13,0) -> רצועת עזה | R4: Official Report | S4: Text | T4: Murder, Torture, Forced Displacement, Sexual Violence | V4: Kamal Adwan Hospital
A5: 2387 | B5: https://www.idi.org.il/articles/57946 | C5: Poll - 57.5% of Israeli Public Support Complete Hostage Deal in Return for End of War (Jan 2025) | D5: =VLOOKUP(A5,Hebrew!A:C,3,0) -> סקר דצמבר 2024: רוב הציבור (57.5%) תומך בעסקה כוללת לשחרור כול החטופים בתמורה לסיום המלחמה | E5: A survey conducted in December 2024 by the Israeli Democracy Institute shows public support for a comprehensive deal to release all captives in exchange for ending the war, with varying opinions across political spectrums. | F5: =VLOOKUP($A5,Hebrew!$A:$S,4,0) -> סקר שערך מכון הישראלי לדמוקרטיה מצא, בין שאר הנושאים, רוב גדול התומך בעסקה כוללת לשחרור החטיפים בתמורה לסיום המלחמה. | G5: January 15, 2025 | H5: 45658 | I5: January 8, 2025 | J5: The Israel Democracy Institute | K5: Prof. Tamar Herman, Dr. Lior Yohanani, Yaron Kaplan, Inna Orly Sapojnikov | L5: =VLOOKUP($A5,Hebrew!$A:$S,9,0) -> פרופ' תמר הרמן, ד"ר ליאור יוחנני, ירון קפלן, אינה אורלי ספוז'ניקוב | N5: https://dataisrael.idi.org.il | O5: Hebrew | P5: Israel | Q5: =VLOOKUP($A5,Hebrew!$A:$S,13,0) -> ישראל | R5: Analysis | S5: Text | T5: Hostage Deal, Ceasefire, Public Opinion, Israeli Society | U5: IDF (Israel Defense Forces) | V5: Israel
A6: 2388 | B6: https://www.mekomit.co.il/%d7%9c%d7%94%d7%a8%d7%95%d7%a1-%d7%90%d7%aa-%d7%94%d7%a9%d7%9c%d7%99%d7%97-%d7%9b%d7%9a-%d7%94%d7%97%d7%a8%d7%99%d7%91%d7%94-%d7%99%d7%a9%d7%a8%d7%90%d7%9c-%d7%90%d7%aa-%d7%9e%d7%aa%d7%a7%d7%a0%d7%99/ | C6: Israel's destruction of journalistic infrastructure in Gaza | D6: =VLOOKUP(A6,Hebrew!A:C,3,0) -> להרוס את השליח: כך החריבה ישראל את מתקני העיתונות בעזה | E6: Israel's destruction of media facilities in Gaza, as investigated by Forbidden Stories, highlights the challenges faced by journalists in reporting from the region. | F6: =VLOOKUP($A6,Hebrew!$A:$S,4,0) -> תחקיר של פורבידן סטוריז ושיחה מקומית בעקבות הפגיעה בעיתונאים ובמשרדיהם. | G6: June 26, 2024 | H6: October 7, 2023 | I6: June 25, 2024 | J6: Mekomit | K6: Léa Peruchon | L6: =VLOOKUP($A6,Hebrew!$A:$S,9,0) -> לאה פרושון | O6: Hebrew | P6: Gaza City | Q6: =VLOOKUP($A6,Hebrew!$A:$S,13,0) -> עיר עזה | R6: Journalistic report | S6: Text | T6: Media, Civilians, Air Strike, Rules of Engagement, Journalists, War Crimes | V6: Gaza City
A7: 2389 | B7: https://www.haaretz.co.il/news/magazine/2024-06-25/ty-article-magazine/.premium/00000190-4ac5-da42-a1ba-7fef27c50000 | C7: IDF reserve soldiers refusing to serve further tell their stories | D7: =VLOOKUP(A7,Hebrew!A:C,3,0) -> שלושה חיילי מילואים מספרים מדוע יסרבו לשרת בעזה גם אם ישלמו על כך | E7: Three reserve soldiers explain why they will refuse to serve in Gaza, even if they will face consequences. | F7: =VLOOKUP($A7,Hebrew!$A:$S,4,0) -> שלושה חיילי מילואים מסבירים מדוע חתמו על מכתב סירוב לשרת בעזה | G7: June 25, 2024 | H7: May 31, 2024 | J7: Haaretz | K7: Liza Rozovsky | L7: =VLOOKUP($A7,Hebrew!$A:$S,9,0) -> ליזה רוזובסקי | O7: Hebrew | P7: Gaza Strip | Q7: =VLOOKUP($A7,Hebrew!$A:$S,13,0) -> רצועת עזה | R7: Journalistic report | S7: Text | T7: War Crimes, Rules of Engagement, Ground Operation, Hostage Deal | U7: IDF (Israel Defense Forces) | V7: Gaza Strip
A8: 2390 | B8: https://zeteo.com/p/the-myth-of-human-shields-israel-gaza | C8: The Myth of Gaza's civilian population serving as human shields for Hamas | D8: =VLOOKUP(A8,Hebrew!A:C,3,0) -> המיתוס של 'מגינים אנושיים' | E8: The article debunks the 'human shields' claim used by Israel in Gaza conflicts, highlighting the impact on civilians and the misuse of the term by the Israeli military. | F8: =VLOOKUP($A8,Hebrew!$A:$S,4,0) -> המאמר חושף את השימוש לראה בטיעון 'מגינים אנושיים' בו משתמש הצבא הישראלי ברצועת עזה, וחושף את השפעתו על האוכלוסייה האזרחית | G8: September 30, 2024 | J8: Zeteo | K8: Muhammad Shehada | L8: =VLOOKUP($A8,Hebrew!$A:$S,9,0) -> מוחמד שחאדה | O8: English | P8: Gaza Strip | Q8: =VLOOKUP($A8,Hebrew!$A:$S,13,0) -> רצועת עזה | R8: Opinion | S8: Text | T8: Civilians, Rules of Engagement, Air Strike, Collective Punishment | V8: Gaza Strip
A9: 2391 | B9: https://www.gazahealthcareletters.org/usa-letter-oct-2-2024 | C9: Letter to US President Biden and Vice President Harris from 99 American physicians who volunteered in Gaza | D9: =VLOOKUP(A9,Hebrew!A:C,3,0) -> מכתב 99 רופאים שהתנדבו לשרת בעזה לנשיא ארה"ב ביידן ולסגניתו האריס | E9: American medical professionals who served in Gaza write an open letter to President Biden and Vice President Harris, urging for immediate action to prevent further catastrophe in Gaza and Israel. | F9: =VLOOKUP($A9,Hebrew!$A:$S,4,0) -> במכתב פתוח לנשיא ארה"ב ביידן ולסגניתו האריס פונים אנשי צוותי רפואה אמריקנים לפעול בדחיות למנוע המשך הקטקסטרופה בעזה ובישראל. | G9: October 2, 2024 | H9: October 7, 2023 | I9: 45566 | J9: Gaza Healthcare Letters | K9: American Medical Professionals who Served in Gaza | L9: =VLOOKUP($A9,Hebrew!$A:$S,9,0) -> צוותי רפואה אמריקנים שפעלו בעזה | O9: English | P9: Gaza Strip | Q9: =VLOOKUP($A9,Hebrew!$A:$S,13,0) -> רצועת עזה | R9: Open letter | S9: Text | T9: Civilians, Hospital, Public Health, Torture | U9: United States | V9: Gaza Strip | W9: Joe Biden, Kamala Harris
A10: 2392 | B10: https://www.haaretz.co.il/news/politics/2024-10-30/ty-article-magazine/.premium/00000192-de9d-d7b5-af97-ff9d2d0d0000 | C10: 100 dead in IDF attempt to kill a spotter | D10: =VLOOKUP(A10,Hebrew!A:C,3,0) -> איך אפשר להפציץ בניין על כל יושביו?: בבית לאהיא מחפשים ניצולים במבנה שקרס | E10: Residents and rescue workers search for survivors in a collapsed five-story building in Beit Lahia, northern Gaza Strip, following an explosion that occurred the previous morning. | F10: =VLOOKUP($A10,Hebrew!$A:$S,4,0) -> לפי הרשויות בעזה, כמאה בני אדם נהרגו ועוד עשרות נעדרים בתקיפת מבנה מגורים בן חמש קומות בבית לאהיא שאיכלס כ-200 איש. בצה"ל אומרים כי תצפיתן שהה על גג המבנה. אנשי שירותי ההצלה, המשיכו לנסות ולאתר ניצולים. | G10: October 30, 2024 | H10: October 29, 2024 | I10: October 29, 2024 | J10: Haaretz | K10: Jack Khoury | L10: =VLOOKUP($A10,Hebrew!$A:$S,9,0) -> ג'קי חורי | O10: Hebrew | P10: Beit Lahia | Q10: =VLOOKUP($A10,Hebrew!$A:$S,13,0) -> בית לאהיא | R10: Journalistic report | S10: Text | T10: Air Strike, Civilians | V10: Beit Lahiya
A11: 2393 | B11: https://www.theguardian.com/world/article/2024/jul/19/israel-gaza-war-polio-sewage-samples | C11: Polio virus found in Gaza sewage | D11: =VLOOKUP(A11,Hebrew!A:C,3,0) -> וירוס פוליו מדבק התגלה בדגימות ביוב בעזה | E11: Highly infectious poliovirus found in Gaza sewage samples, putting thousands at risk of contracting the disease due to poor sanitation and infrastructure conditions. | F11: =VLOOKUP($A11,Hebrew!$A:$S,4,0) -> וירוס פוליו מדבק התגלה בדגימות ביוב בעזה ומעמיד בסכנה אלפי תושבים בגלל תנאי היגיינה ותשתיות פגועים. | G11: July 19, 2024 | J11: The Guardian | K11: Agence France-Presse | L11: =VLOOKUP($A11,Hebrew!$A:$S,9,0) -> סוכנות הידיעות הצרפתית | O11: English | P11: Gaza Strip | Q11: =VLOOKUP($A11,Hebrew!$A:$S,13,0) -> רצועת עזה | R11: Journalistic report | S11: Text | T11: Water, Public Health | V11: Central Gaza Strip
A12: 2394 | B12: https://www.thenationalnews.com/news/mena/2024/06/21/israel-gaza-city-municipality-garage/ | C12: Israel killed water/environment engineer & municipality officials working to restore water supply in Gaza | D12: =VLOOKUP(A12,Hebrew!A:C,3,0) -> בתקיפה אווירית נהרגו מהנדסי מים ותשתיות נציגי העירייה שפעלו להחזיר לפעולה את אספקת המים | E12: An Israeli airstrike on a Gaza City municipal building kills at least five workers, including four preparing to restore drinking water wells, leading to significant destruction and impacting essential services in the war-torn enclave. | F12: =VLOOKUP($A12,Hebrew!$A:$S,4,0) -> בתקיפה אווירית ישראלית על בנין העירייה של עזה נהרגו לפחות ארבעה שעבדו על חידוש אספקת מים לבארות המים ובכך פגעו אנושות באספקת משאב חיוני בעזה הנצורה. | G12: June 21, 2024 | H12: June 21, 2024 | I12: June 21, 2024 | J12: The National | K12: Nagham Mohanna | L12: =VLOOKUP($A12,Hebrew!$A:$S,9,0) -> נאגהם מוחאנה | O12: English | P12: Gaza City | Q12: =VLOOKUP($A12,Hebrew!$A:$S,13,0) -> עיר עזה | R12: Journalistic report | S12: Text | T12: Air Strike, Civilians, Water | V12: Gaza City
A13: 2395 | B13: https://www.globaltimes.cn/page/202411/1322528.shtml | C13: Gazans boycott local markets due to exhorbitant food prices | D13: =VLOOKUP(A13,Hebrew!A:C,3,0) -> עזתים מחרימים שווקים מקומיים בשל הפקעת מחירים | E13: Markets in Gaza are empty as locals boycott due to soaring prices amid the conflict with Israel, leading to protests and accusations of price manipulation by traders. | F13: =VLOOKUP($A13,Hebrew!$A:$S,4,0) -> שווקים בעזה התרוקנו בשל חרם של העזתים במחאה על האשמת הסוחרים מחירים המופקעים | G13: November 6, 2024 | H13: November 5, 2024 | J13: Global Times | K13: Xinhua | L13: =VLOOKUP($A13,Hebrew!$A:$S,9,0) -> סוכנות הידיעות הסינית | O13: English | P13: Central Gaza; Southern Gaza | Q13: =VLOOKUP($A13,Hebrew!$A:$S,13,0) -> מרכז ודרום רצועת עזה | R13: Journalistic report | S13: Text | T13: Food, Humanitarian Aid | V13: Gaza Strip
A14: 2396 | B14: https://amp.cnn.com/cnn/2024/11/29/middleeast/gaza-bakery-crush-palestinians-killed-intl-latam | C14: 3 Palestinians crushed to death in line to get food | D14: =VLOOKUP(A14,Hebrew!A:C,3,0) -> בתור לאוכל נמחצו למוות אישה ושני ילדים פלסטינים | E14: Three Palestinians, including two children and a woman, were crushed to death outside a bakery in Gaza amid a worsening food crisis in the enclave. | F14: =VLOOKUP($A14,Hebrew!$A:$S,4,0) -> על רקע מצוקת המזון הגוברת ברצונת עזה נמחצו למוות אישה ושני ילדים פלסטינים בתור למאפיה. | G14: November 30 ,2024 | H14: November 29, 2024 | I14: November 29, 2024 | J14: CNN | K14: Abeer Salman; Mohammad Al Sawalhi; Ibrahim Dahman; Mitchell McCluskey | L14: =VLOOKUP($A14,Hebrew!$A:$S,9,0) -> אביר סלמאן, מוחמד אל-סוואלי, איברהים דמאן, מישל מק'לאסקי | O14: English | P14: Central Gaza | Q14: =VLOOKUP($A14,Hebrew!$A:$S,13,0) -> מרכז רצועת עזה | R14: Journalistic report | S14: Text | T14: Humanitarian Aid, Food, Civilians | V14: Central Gaza Strip
A15: 2397 | B15: https://thebaffler.com/latest/running-amok-turfah | C15: Dehumanizing social media posts by Israeli soldiers in Gaza | D15: =VLOOKUP(A15,Hebrew!A:C,3,0) -> דהומנציזציה של הפלסטינים מוצגת על ידי חיילים ישראלים בסרטונים במדיה החברתית | E15: The content discusses various disturbing behaviors exhibited by Israeli soldiers in Gaza, including destruction, looting, and disrespectful actions towards Palestinians. | F15: =VLOOKUP($A15,Hebrew!$A:$S,4,0) -> בסרטונים תכנים מטרידים של חיילי ישראל, כולל תיאורי הרס, ביזה והתנהגות לא מכובדת כלפי פלסטינים | G15: June 18, 2024 | J15: The Baffler | K15: Mary Turfah | L15: =VLOOKUP($A15,Hebrew!$A:$S,9,0) -> מרי טורפה | O15: English | P15: Gaza Strip | Q15: =VLOOKUP($A15,Hebrew!$A:$S,13,0) -> רצועת עזה | R15: Journalistic report | S15: Text | T15: Vandalism | U15: IDF (Israel Defense Forces) | V15: Gaza Strip
A16: 2398 | B16: https://www.haaretz.com/israel-news/2024-09-03/ty-article/.premium/israeli-army-reservists-assault-gazan-truck-drivers-working-for-aid-organizations/00000191-b71d-d13c-a39b-bf9d24710000 | C16: Israeli army reservist assault Gazan truck drivers working for aid organizations | D16: =VLOOKUP(A16,Hebrew!A:C,3,0) -> חיילי מילואים תוקפים נהגי משאיות עזתים העובדים עבור ארגוני סיוע | E16: Israeli army reservists assaulted Gazan truck drivers working for aid organizations, despite being cleared by Israel's security services. | F16: =VLOOKUP($A16,Hebrew!$A:$S,4,0) -> חיילי מילואים תוקפים נהגי משאיות עזתים העובדים עבור ארגוני סיוע למרות שיש להם אישור מכוחות הביטחון | G16: September 3, 2024 | H16: 45505 | J16: Haaretz | K16: Yaniv Kubovich | L16: =VLOOKUP($A16,Hebrew!$A:$S,9,0) -> יניב קובוביץ | O16: English | P16: Kerem Shalom Crossing | Q16: =VLOOKUP($A16,Hebrew!$A:$S,13,0) -> מעבר כרם שלום | R16: Journalistic report | S16: Text | T16: Humanitarian Aid, Civilians | U16: IDF (Israel Defense Forces) | V16: Kerem Shalom Crossing
A17: 2399 | B17: https://www.themarker.com/news/education/2024-09-30/ty-article/00000192-41e6-d07b-aff3-57e6401a0000 | C17: Israeli Ministry of Education Directorate of Religious Education calls for schools to celebrate killing of Hezbollah leader Hassan Nasrallah | D17: =VLOOKUP(A17,Hebrew!A:C,3,0) -> משרד החינוך קרא לבתי הספר לערוך הרקדות ומשלוחי מנות לתלמידים עקב חיסול נסראללה | E17: The Ministry of Education instructed religious state schools to hold dances and send food packages to students following the killing of Hezbollah leader Hassan Nasrallah, sparking debates within the religious community. | F17: =VLOOKUP($A17,Hebrew!$A:$S,4,0) -> מינהל החינוך הדתי במשרד החינוך, האחראי על הפיקוח על רבני בתי הספר הממלכתיים־דתיים, הנחה בתי ספר לערוך חגיגות לציון הרג מנהיג חיזבאללה. היו גורמים במשרד שמתחו ביקורת על המהלך | G17: September 30, 2024 | H17: September 29, 2024 | I17: September 29, 2024 | J17: The Marker | K17: Lior Dattel | L17: =VLOOKUP($A17,Hebrew!$A:$S,9,0) -> ליאור דטל | O17: Hebrew | P17: Israel | Q17: =VLOOKUP($A17,Hebrew!$A:$S,13,0) -> ישראל | R17: Journalistic report | S17: Text | T17: Israeli Society | V17: Israel | W17: Hassan Nasrallah
A18: 2400 | B18: https://www.haaretz.co.il/news/law/2024-09-23/ty-article/.premium/00000192-1b6b-d342-ab9f-df6b2b790000 | C18: Deputy Mayor of Jerusalem interrogated under suspicion of inciting to violence and terrorism | D18: =VLOOKUP(A18,Hebrew!A:C,3,0) -> סגן ראש העיר ירושלים נחקר בחשד להסתה לטרור לאחר שפרסם פוסטים נגד אונר"א | E18: Jerusalem's Deputy Mayor, Aryeh King, is under investigation for incitement to violence and terrorism after posting against the UN - Law and Crime | F18: =VLOOKUP($A18,Hebrew!$A:$S,4,0) -> סגן ראש העיר ירושלים נחקר בחשד להסתה לאלימות והסתה לטרור לאחר שפרסם פוסטים נגד אונר"א ועידוד לשריפת מבני אונר"א | G18: September 23, 2024 | H18: September 23, 2024 | J18: Haaretz | K18: Yael Freidson | L18: =VLOOKUP($A18,Hebrew!$A:$S,9,0) -> יעל פרידסון | O18: Hebrew | P18: Israel | Q18: =VLOOKUP($A18,Hebrew!$A:$S,13,0) -> ישראל | R18: Journalistic report | S18: Text | T18: Terrorism | U18: Israeli Police, UNRWA (The UN Relief and Works Agency for Palestine Refugees) | V18: Jerusalem
A19: 2401 | B19: https://www.nytimes.com/2024/10/14/world/middleeast/israel-gaza-military-human-shields.html | C19: Israeli Army uses Palestinian civilians as human shields in Gaza | D19: =VLOOKUP(A19,Hebrew!A:C,3,0) -> צה"ל משתמש באזרחים פלסטינים כמגינים חיים בעזה. | E19: Israeli soldiers have been accused of using Palestinians as human shields in Gaza, forcing them to carry out dangerous tasks, as reported by The New York Times. | F19: =VLOOKUP($A19,Hebrew!$A:$S,4,0) -> חיילי צה"ל לפי דיווח בניו יורק טיימס מאלצים אזרחים פלסטינים לשמש כמגינים חיים ולבצע משימות מסכנות חיים. | G19: October 14, 2024 | J19: The New York Times | K19: Natan Odenheimer; Bilal Shbair; Patrick Kingsley | L19: =VLOOKUP($A19,Hebrew!$A:$S,9,0) -> נתן אודנהיימר, בילאל שבאר, פטריק קינגסלי | O19: English | P19: Gaza Strip | Q19: =VLOOKUP($A19,Hebrew!$A:$S,13,0) -> רצועת עזה | R19: Journalistic report | S19: Text | T19: Ground Operation, Civilians | U19: IDF (Israel Defense Forces) | V19: Gaza Strip
A20: 2402 | B20: https://www.haaretz.co.il/news/magazine/2024-06-28/ty-article-magazine/.premium/00000190-5aa7-de5e-abd0-fbf704260000 | C20: A night with an IDF ghost unit that has been fighting in the Gaza Strip for eight months | D20: =VLOOKUP(A20,Hebrew!A:C,3,0) -> לילה עם יחידת רפאים של צה"ל, שנלחמת ברצועה כבר שמונה חודשים | E20: An article about a night with the IDF's Re'phaim unit, which has been fighting in the Gaza Strip for eight months. | F20: =VLOOKUP($A20,Hebrew!$A:$S,4,0) -> לילה עם יחידת רפאים של צה"ל, שמכונה גם היחידה הרב-ממדית, שתפקידה לאתר ולפגוע במחבלים בעומק שטח הלחימה באמצעות יכולות טכנולוגיות מתקדמות | G20: June 28,2024 | H20: June 21, 2024 | J20: Haaretz | K20: Yaniv Kubovich | L20: =VLOOKUP($A20,Hebrew!$A:$S,9,0) -> יניב קובוביץ | O20: Hebrew | P20: Gaza Strip | Q20: =VLOOKUP($A20,Hebrew!$A:$S,13,0) -> רצועת עזה | R20: Journalistic report | S20: Text | T20: Hostages | U20: IDF (Israel Defense Forces) | V20: Gaza Strip
A21: 2403 | B21: https://www.haaretz.co.il/news/politics/2024-10-16/ty-article/.premium/00000192-94aa-d9c2-a7f3-9cae337a0000 | C21: An invitation from Likud for an event in the Gaza border area was distributed under the title 'Preparing to settle in the Gaza region | D21: =VLOOKUP(A21,Hebrew!A:C,3,0) -> הזמנה מטעם הליכוד לאירוע בעוטף הופצה תחת הכותרת "נערכים להתיישב בחבל עזה" | E21: The Likud party has issued an invitation for an event in the Gaza envelope titled 'Preparing to settle in the Gaza Strip' with the participation of several Likud Knesset members. | F21: =VLOOKUP($A21,Hebrew!$A:$S,4,0) -> לפי ההזמנה, הליכוד יקים סוכה כחלק מ"עיר סוכות" בעוטף עזה של תנועת "נחלה", שפועלת להקמת מאחזים בלתי חוקיים בגדה. בהזמנה נכתב כי ח"כים מהליכוד צפויים להגיע | G21: October 16,2024 | J21: Haaretz | K21: Noa Spigel | L21: =VLOOKUP($A21,Hebrew!$A:$S,9,0) -> נועה שפיגל | O21: Hebrew | P21: Western Negev (Otef) | Q21: =VLOOKUP($A21,Hebrew!$A:$S,13,0) -> עוטף עזה | R21: Journalistic report | S21: Text | T21: Israeli Society, Settlements | V21: Western Negev (Otef) | W21: Benny Gantz, Benjamin Netanyahu
A22: 2404 | B22: https://www.mekomit.co.il/ps/141796/ | C22: The children of Gaza have started the school year amid destruction, loss, and uncertainty | D22: =VLOOKUP(A22,Hebrew!A:C,3,0) -> ילדי עזה החלו את שנת הלימודים בתוך חורבן, אובדן ואי ודאות | E22: Children in Gaza begin the school year amidst destruction and uncertainty, facing challenges in accessing education due to ongoing attacks and war aftermath. | F22: =VLOOKUP($A22,Hebrew!$A:$S,4,0) -> מורים ואנשי חינוך בעזה החרבה מנסים לספק לילדים תוכניות חינוכיות בכיתות, באוהלים או במבנים הרוסים, אך ספק אם התוכניות האלה ישרדו תחת ההתקפות המתמשכות והחורף המתקרב | G22: October 31, 2024 | J22: Mekomit | K22: Rawida Kamal Amar;Ivtisam Mahdi | L22: =VLOOKUP($A22,Hebrew!$A:$S,9,0) -> רווידה כמאל עמאר ואיבתיסאם מהדי | N22: https://www.ochaopt.org/content/reported-impact-snapshot-gaza-strip-29-october-2024 | O22: Hebrew | P22: Gaza Strip | Q22: =VLOOKUP($A22,Hebrew!$A:$S,13,0) -> רצועת עזה | R22: Journalistic report | S22: Text | T22: Scholasticide | V22: Gaza Strip
A23: 2405 | B23: https://www.kan.org.il/content/kan-news/defense/827036/ | C23: With the help of soldiers: This is how the right-wing activist managed to enter Netzarim | D23: =VLOOKUP(A23,Hebrew!A:C,3,0) -> תחקיר זמן אמת: בסיוע חיילים הצליחה פעילת הימין להיכנס לנצרים | E23: Israeli Right-wing settler activist Daniella Weiss enlisted the help of military forces stationed in and around the Gaza Strip to enter the territory despite it being declared a closed military zone. Weiss did so in preparation for establishing Jewish settlements in the Gaza Strip. | F23: =VLOOKUP($A23,Hebrew!$A:$S,4,0) -> רכב צבאי הסיע את דניאלה וייס, ממייסדות תנועת ההתיישבות, לתוך שטח צבאי סגור ברצועת עזה. שלטונות הצבא היו מודעים לכך. | G23: November 21, 2024 | H23: November 13, 2024 | J23: Kan 11 | K23: Avi Amit | L23: =VLOOKUP($A23,Hebrew!$A:$S,9,0) -> אבי עמית | O23: Hebrew | P23: Gaza Strip | Q23: =VLOOKUP($A23,Hebrew!$A:$S,13,0) -> רצועת עזה | R23: Journalistic report | S23: Text | T23: Religious Right, Settlements | U23: IDF (Israel Defense Forces) | V23: Gaza Strip
A24: 2406 | B24: https://www.haaretz.co.il/news/politics/2025-01-18/ty-article/00000194-784f-d739-a9b6-78ff31ab0000 | C24: Israel has committed to allowing reconstruction work in the Gaza Strip at the beginning of the first phase of the deal | D24: =VLOOKUP(A24,Hebrew!A:C,3,0) -> ישראל התחייבה לאפשר קיום עבודות לשיקום הרצועה בתחילת השלב הראשון של העסקה | E24: Israel committed to allowing infrastructure rehabilitation works in the Gaza Strip at the beginning of the first stage of the agreement, amidst the release of captives and ceasefire negotiations. | F24: =VLOOKUP($A24,Hebrew!$A:$S,4,0) -> במסגרת ההסכם יוקמו ערי קראוונים לתושבי הרצועה במימון בינלאומי. לאחר שהממשלה אישרה הלילה את העסקה, הודיע דובר משרד החוץ הקטארי כי הפסקת האש תיכנס לתוקף מחר ב-8:30. חמאס מחויב לשלוח לישראל היום את שמות שלוש החטופות הראשונות שישוחררו | G24: January 18, 2025 | J24: Haaretz | K24: Yaniv Kubovich, Yehonatan Lis | L24: =VLOOKUP($A24,Hebrew!$A:$S,9,0) -> יניב קובוביץ ויהונתן ליס | O24: Hebrew | P24: North Gaza Strip | Q24: =VLOOKUP($A24,Hebrew!$A:$S,13,0) -> צפון רצועת עזה | R24: Journalistic report | S24: Text | T24: Hostage Deal, Reconstruction, Ceasefire | U24: Qatar | V24: North Gaza
A25: 2407 | B25: https://www.nytimes.com/2024/11/19/world/middleeast/israel-5-million-dollars-hostage.html | C25: Netanyahu Offers $5 Million for Each Hostage Freed in Gaza | D25: =VLOOKUP(A25,Hebrew!A:C,3,0) -> נתניהו מציע 5 מיליון דולר עבור כל חטוף שישוחרר | E25: Israeli Prime Minister Netanyahu offers $5 million for each hostage freed in Gaza as part of efforts to secure their release amidst stalled cease-fire talks. | F25: =VLOOKUP($A25,Hebrew!$A:$S,4,0) -> נתניהו מציע פרס כספי עבור שחרור חטופים תוך שהוא דוחה הצעה להפסקת אש ומאיים להעניש מי שיפגע בחטופים. | G25: November 19, 2024 | J25: The New York Times | K25: Efrat Livni | L25: =VLOOKUP($A25,Hebrew!$A:$S,9,0) -> אפרת ליבני | O25: English | Q25: =VLOOKUP($A25,Hebrew!$A:$S,13,0) -> 0 | R25: Journalistic report | S25: Text | T25: Hostage Deal, Hostages | W25: Benjamin Netanyahu, Yoav Gallant
A26: 2408 | B26: https://www.ha-makom.co.il/idf-droppings/ | C26: Silent and suppressed refusal: Active-duty soldiers are no longer willing to keep fighting | D26: =VLOOKUP(A26,Hebrew!A:C,3,0) -> סרבנות שקטה ומושתקת: לוחמים בסדיר לא מוכנים יותר להמשיך להילחם | E26: Israeli soldiers in the Nahal Brigade express reluctance to continue fighting in Gaza due to mental and emotional strain, leading to a phenomenon of quiet refusal to engage in combat. | F26: =VLOOKUP($A26,Hebrew!$A:$S,4,0) -> מנח״ל ועד חטיבת הקומנדו, מגבעתי ועד הצנחנים - יותר ויותר לוחמים, מכלל יחידות החי״ר, מעידים שהשחיקה והאטימות של צה"ל לא הותירה להם ברירה אלא לסרב | G26: October 15, 2024 | J26: Ha-Makom | K26: Revital Hovel | L26: =VLOOKUP($A26,Hebrew!$A:$S,9,0) -> רביטל חובל | O26: Hebrew | Q26: =VLOOKUP($A26,Hebrew!$A:$S,13,0) -> 0 | R26: Journalistic report | S26: Text | T26: Israeli Society | U26: IDF (Israel Defense Forces)
A27: 2409 | B27: https://www.haaretz.co.il/news/politics/2024-08-02/ty-article/.premium/00000191-1442-db7e-a99d-1edabb590000 | C27: Senior negotiator: Security officials believe that Netanyahu is not interested in advancing a deal | D27: =VLOOKUP(A27,Hebrew!A:C,3,0) -> בכיר בצוות המו"מ: ראשי מערכת הביטחון מעריכים שנתניהו לא מעוניין לקדם עסקה | E27: Senior member of the negotiation team states that security system heads believe Netanyahu is not interested in advancing a deal. | F27: =VLOOKUP($A27,Hebrew!$A:$S,4,0) -> ידיעות על משבר ביחסים בין נתניהו למערכת הביטחון. במערכת הביטחון, וכן בארה"ב בקטאר ובמצרים, מעריכים כבר חודשים ארוכים כי נתניהו אינו מעוניין בעסקה. זאת, בין היתר כדי לשמור על שרידות הממשלה שלו. | G27: August 02, 2024 | J27: Haaretz | K27: Michael Houzertov, Yehonatan Lis, Bar Peleg | L27: =VLOOKUP($A27,Hebrew!$A:$S,9,0) -> מיכאל האוזר טוב, יהונתן ליס ובר פלג | O27: Hebrew | P27: Gaza Strip | Q27: =VLOOKUP($A27,Hebrew!$A:$S,13,0) -> רצועת עזה | R27: Journalistic report | S27: Text | T27: Hostage Deal | U27: Shin Bet | V27: Netzarim Corridor, Philadelphi Corridor | W27: Ronen Bar, Benjamin Netanyahu
A28: 2410 | B28: https://www.haaretz.co.il/news/politics/2025-01-19/ty-article/.premium/00000194-7d23-de1b-a9bd-7d67f9790000 | C28: The IDF and Shin Bet retrieved from the Gaza Strip the body of soldier Oron Shaul, who was killed in Operation Protective Edge in 2014 | D28: =VLOOKUP(A28,Hebrew!A:C,3,0) -> צה"ל ושב"כ חילצו מרצועת עזה את גופתו של החייל אורון שאול שנהרג במבצע צוק איתן ב-2014 | E28: IDF and Shin Bet extracted the body of soldier Oron Shaul, who was killed in Operation Protective Edge in 2014, from the Gaza Strip. | F28: =VLOOKUP($A28,Hebrew!$A:$S,4,0) -> גופתו של שאול נחטפה למנהרה בשג'אעייה לאחר שטיל RPG נורה על הנגמ"ש שבו היה עם חבריו. כוחות מיוחדים, בהם לוחמי שייטת 13, השתתפו בהשבתו לישראל. צה"ל: מחויבים להשיב גם את הדר גולדין ושאר החטופים | G28: January 19, 2025 | J28: Haaretz | K28: Michael Houzertov, Adi Hashmonai, Bar Peleg | L28: =VLOOKUP($A28,Hebrew!$A:$S,9,0) -> יניב קובוביץ, עדי חשמונאי ובר פלג | O28: Hebrew | Q28: =VLOOKUP($A28,Hebrew!$A:$S,13,0) -> 0 | R28: Journalistic report | S28: Text | T28: Hostages | U28: IDF (Israel Defense Forces)
A29: 2411 | B29: https://www.haaretz.co.il/gallery/media/2024-08-19/ty-article/.premium/00000191-69da-d12a-a3b5-7dff33f80000 | C29: The Srugim website published an article supporting Jewish terrorism against Palestinians | D29: =VLOOKUP(A29,Hebrew!A:C,3,0) -> אתר "סרוגים" פירסם מאמר שתומך בטרור יהודי נגד פלסטינים | E29: The news website Srugim published an article expressing support for Jewish terrorism against Palestinians. | F29: =VLOOKUP($A29,Hebrew!$A:$S,4,0) -> בתגובה למהומות המתנחלים בג'ית שבהן נורה פלסטיני למוות, פרסם סמנכ"ל "חוננו" לשעבר, אורי קירשנבום, באתר החדשות הדתי־לאומי "סרוגים", טור תחת הכותרת "דין ג'ית כדין רפיח": "שמישהו יסביר לי למה מה שנכון בעזה לא נכון בג'נין, בחברון ובשכם" | G29: August 19 2024 | J29: Haaretz | K29: Ido David Cohen | L29: =VLOOKUP($A29,Hebrew!$A:$S,9,0) -> עדו דוד כהן | O29: Hebrew | P29: West Bank | Q29: =VLOOKUP($A29,Hebrew!$A:$S,13,0) -> הגדה המערבית | R29: Journalistic report | S29: Text | T29: Religious Right | V29: West Bank, Zaytun Neighborhood
A30: 2412 | B30: https://www.haaretz.co.il/magazine/2024-10-10/ty-article-magazine/.highlight/00000192-70ab-d292-a392-78bfa8210000?utm_source=App_Share&utm_medium=Android_Native&utm_campaign=Share | C30: Netanyahu's government is not just allowing Jewish terrorism in the West Bank—it is funding it. Investigation | D30: =VLOOKUP(A30,Hebrew!A:C,3,0) -> ממשלת נתניהו לא סתם מאפשרת את הטרור היהודי בגדה. היא מממנת אותו. תחקיר | E30: An investigation into the funding of Jewish terrorism in the West Bank by the Netanyahu government. | F30: =VLOOKUP($A30,Hebrew!$A:$S,4,0) -> המתנחלים מדברים על זה במונחים של מהפכה: במקום התנחלויות מגודרות על הגבעות, הוקמו בתוך שבע שנים יותר מ–60 חוות שהשתלטו על מאות אלפי דונם בגדה. הפרויקט הנוסק הזה, שמתבסס על כוח עבודה של בני נוער שנפלטו ממסגרות, הפך למחולל המרכזי של אלימות נגד פלסטינים. והוא ממומן בעשרות מיליונים בידי המדינה | G30: October 10, 2024 | J30: Haaretz | K30: Hilo Glazer, Hafar Sheizaf | L30: =VLOOKUP($A30,Hebrew!$A:$S,9,0) -> הילו גלזר, הגר שיזף | O30: Hebrew | P30: West Bank | Q30: =VLOOKUP($A30,Hebrew!$A:$S,13,0) -> הגדה המערבית | R30: Journalistic report | S30: Text | T30: Religious Right, Settlements | U30: Israeli Government | V30: West Bank
A31: 2413 | B31: https://www.ynet.co.il/news/article/bkldluke1e#autoplay | C31: During a visit to the Civil Administration, Smotrich said he is working to shut it down: 'I spoke with Netanyahu' | D31: =VLOOKUP(A31,Hebrew!A:C,3,0) -> בביקור במנהל האזרחי אמר סמוטריץ' כי הוא פועל לסגור אותו: "דיברתי עם נתניהו | E31: Bezalel Smotrich, Minister of Treasury and Minister of Security, is working towards closing the Israeli Civil Administration in the West Bank, as part of a move to annex the territory to Israel de-facto. | F31: =VLOOKUP($A31,Hebrew!$A:$S,4,0) -> שר האוצר רוצה לנצל את מומנטום כניסת ממשל טראמפ, ולקדם את סיפוח יהודה ושומרון והחלת ריבונות על השטח. הכתבה מרחיבה על המשמעויות הדרמטיות של צעד כזה | G31: December 5, 2024 | J31: Ynet | K31: Elisha Ben-kimon | L31: =VLOOKUP($A31,Hebrew!$A:$S,9,0) -> אלישע בן קימון | O31: Hebrew | P31: West Bank | Q31: =VLOOKUP($A31,Hebrew!$A:$S,13,0) -> הגדה המערבית | R31: Journalistic report | S31: Text | T31: Religious Right, Annexation | U31: Israeli Government | V31: West Bank | W31: Bezalel Smotritch
A32: 2414 | B32: https://www.haaretz.co.il/news/politics/2025-01-09/ty-article/.premium/00000194-45b1-db19-abdd-6db7c86d0000 | C32: Ben Gvir demands that the police prioritize the demolition of illegal buildings that house families | D32: =VLOOKUP(A32,Hebrew!A:C,3,0) -> בן גביר דורש מהמשטרה לתעדף הריסת מבנים לא חוקיים שמאכלסים משפחות | E32: Minister Itamar Ben Gvir intervenes in the police enforcement policy regarding the demolition of illegal buildings housing families. | F32: =VLOOKUP($A32,Hebrew!$A:$S,4,0) -> השר לביטחון לאומי איתמר בן גביר התערב במדיניות האכיפה של המשטרה בהריסת מבנים לא חוקיים, והורה לבכירים בארגון לתעדף הריסת בתים המאוכלסים על ידי משפחות על אף שאין לו הסמכות לקבוע את מדיניות ההריסה | G32: January 9, 2025 | J32: Haaretz | K32: Josh Breiner | L32: =VLOOKUP($A32,Hebrew!$A:$S,9,0) -> יהושע (ג'וש) בריינר | O32: Hebrew | P32: Negev | Q32: =VLOOKUP($A32,Hebrew!$A:$S,13,0) -> נגב | R32: Journalistic report | S32: Text | T32: Religious Right | U32: Israeli Police | V32: Negev | W32: Itamar Ben-Gvir
A33: 2415 | B33: https://www.haaretz.co.il/news/politics/2024-10-30/ty-article/.premium/00000192-d9c2-d605-a3b2-dfc702430000 | C33: In the Shuafat refugee camp, residents do not believe that the authorities will take over UNRWA's role | D33: =VLOOKUP(A33,Hebrew!A:C,3,0) -> במחנה הפליטים שועפט לא מאמינים שהרשויות ייכנסו לנעלי אונר"א | E33: The article discusses the living conditions in the Shuafat refugee camp, managed by the UN agency UNRWA, and the potential legal implications of a recent law passed in the Knesset. | F33: =VLOOKUP($A33,Hebrew!$A:$S,4,0) -> כמו בהחלטות רבות שנוגעות לירושלים מאז 1967, גם החוק לסילוק אונר"א לא הגיע על רקע רצון לפתור בעיה כלשהי, להקל על תושבי ירושלים או לקדם עתיד טוב יותר. גם אם יש בעיות בסוכנות, לא מדובר בארגון טרור, אלא בארגון שמספק שירותים חיוניים למאות אלפי בני אדם | G33: October 30, 2024 | J33: Haaretz | K33: Nir Hasson | L33: =VLOOKUP($A33,Hebrew!$A:$S,9,0) -> ניר חסון | O33: Hebrew | P33: East Jerusalem | Q33: =VLOOKUP($A33,Hebrew!$A:$S,13,0) -> מזרח ירושלים | R33: Opinion | S33: Text | U33: UN (United Nations) | V33: Jerusalem
A34: 2416 | B34: https://www.haaretz.co.il/news/politi/2024-11-13/ty-article/.premium/00000193-24ee-d76b-afd7-a7ff70930000 | C34: Approved in a preliminary vote: The police will be able to access a computer or personal phone without the owner's knowledge | D34: =VLOOKUP(A34,Hebrew!A:C,3,0) -> אושר בטרומית: המשטרה תוכל לחדור למחשב או לטלפון אישי בלא ידיעת בעליו | E34: The Knesset approved a controversial bill allowing police officers to access personal computers or phones without the owner's knowledge, sparking opposition concerns about the legality of the process. | F34: =VLOOKUP($A34,Hebrew!$A:$S,4,0) -> מליאת הכנסת אישרה בקריאה טרומית הצעה, לפיה קצין בדרגת ניצב־משנה ומעלה יוכל לבקש אישור מנשיא בית המשפט המחוזי או מסגנו לחדור למחשבים אישיים ולהעתיק מהם חומרים, אם שוכנע שהפעולה נדרשת למניעת "פשע חמור". החוק לא יחול על עבירות שחיתות כגון שוחד, מרמה והפרת אמונים | G34: November 13, 2024 | J34: Haaretz | K34: Noa Shpigel | L34: =VLOOKUP($A34,Hebrew!$A:$S,9,0) -> נעה שפיגל | O34: Hebrew | P34: Israel | Q34: =VLOOKUP($A34,Hebrew!$A:$S,13,0) -> ישראל | R34: Journalistic report | S34: Text | T34: Civilians | U34: Israeli Police | V34: Israel
A35: 2417 | B35: https://www.lemonde.fr/en/les-decodeurs/article/2024/10/13/why-the-gaza-health-ministry-s-death-count-is-considered-reliable_6729264_8.html | C35: Study on MoH death toll being accurate | D35: =VLOOKUP(A35,Hebrew!A:C,3,0) -> מדוע נחשבים הנתונים שמספק משרד הבריאות הפלסטיני בעזה לגבי מספר המתים אמינים? | E35: The article discusses the reliability of the death count provided by the Gaza Health Ministry during the Israel-Gaza conflict, detailing the methodology used and the challenges faced in accurately reporting casualties. | F35: =VLOOKUP($A35,Hebrew!$A:$S,4,0) -> המאמר סוקר את חילוקי הדעות לגבי נתונים שמספק משרד הבריאות בעזה. במאמר נטען שהנתונים אמינים ומקובלים. | G35: October 13, 2024 | J35: Le Monde | K35: Assma Maad | L35: =VLOOKUP($A35,Hebrew!$A:$S,9,0) -> אסמה אעד | O35: English | P35: Gaza Strip | Q35: =VLOOKUP($A35,Hebrew!$A:$S,13,0) -> רצועת עזה | R35: Analysis | S35: Text | T35: Civilians | U35: Hamas, Gaza Health Ministry, IDF (Israel Defense Forces) | V35: Gaza Strip
A36: 2418 | B36: https://www.haaretz.co.il/news/law/2024-12-17/ty-article/00000193-d466-d4ec-a5d3-f57f62f00000 | C36: Israeli activists detained for painting a road in Jerusalem a year and a half ago | D36: =VLOOKUP(A36,Hebrew!A:C,3,0) -> פעילים ישראלים נעצרו על צביעת כביש בירושלים לפני שנה וחצי | E36: Two activists were detained for investigation on suspicion of painting a road in Jerusalem in protest over police brutality over a year ago. | F36: =VLOOKUP($A36,Hebrew!$A:$S,4,0) -> שני פעילים נעצרו לחקירה בחשד ששלפני יותר משנה צבעו כביש בירושלים במחאה נגד המהפכה המשטרית. | G36: December 17, 2024 | J36: Haaretz | K36: Bar Peleg | L36: =VLOOKUP($A36,Hebrew!$A:$S,9,0) -> בר פלג | O36: Hebrew | P36: Jerusalem | Q36: =VLOOKUP($A36,Hebrew!$A:$S,13,0) -> ירושלים | R36: Journalistic report | S36: Text | T36: Israeli Society, Vandalism, Protest (Israel) | V36: Jerusalem
A37: 2419 | B37: https://www.nytimes.com/2024/07/25/us/politics/harris-biden-netanyahu-meeting-israel.html?campaign_id=9&emc=edit_nn_20240726&instance_id=129819&nl=the-morning&regi_id=70279552&segment_id=173210&smid=url-share&te=1&user_id=2e28080c4831073bd853a843a6df3aec | C37: Harris Offers Support for Israel but Calls Out Palestinians’ Plight After Talk With Netanyahu | D37: =VLOOKUP(A37,Hebrew!A:C,3,0) -> הריס מציעה תמיכה לישראל אך מדגישה את מצוקתם של הפלסטינים לאחר שיחה עם נתניהו | E37: Vice President Kamala Harris expresses support for Israel's right to defend itself but also highlights the suffering of Palestinians during a meeting with Prime Minister Benjamin Netanyahu. | F37: =VLOOKUP($A37,Hebrew!$A:$S,4,0) -> סגנית הנשיא קמלה האריס מביעה תמיכה בזכותה של ישראל להגן על עצמה, אך גם מדגישה את הסבל של הפלסטינים במהלך פגישה עם ראש הממשלה בנימין נתניהו. | G37: July 25, 2024 | J37: The New York Times | K37: Peter Baker | L37: =VLOOKUP($A37,Hebrew!$A:$S,9,0) -> פיטר בייקר | O37: English | Q37: =VLOOKUP($A37,Hebrew!$A:$S,13,0) -> 0 | R37: Journalistic report | S37: Text | T37: Civilians, Hostages, Forced Displacement, Starvation | W37: Benjamin Netanyahu, Kamala Harris, Joe Biden
A38: 2420 | B38: https://www.wsj.com/world/middle-east/once-hamass-sworn-enemy-mohammed-dahlan-rises-as-a-postwar-strongman-f64676b1?ref=forever-wars.com | C38: Some U.S., Israeli and Arab officials see Palestinian Mohammed Dahlan as a viable leader of an interim security force | D38: =VLOOKUP(A38,Hebrew!A:C,3,0) -> כמה פקידים אמריקאים, ישראלים וערבים רואים את מוחמד דחלאן הפלסטיני כמנהיג אפשרי של כוח ביטחון זמני אחרי המלחמה. | E38: As part of discussions on the so-called "day after" in Gaza, U.S., Arab, and Israeli officials have proposed that Mohammed Dahlan, formerly head of the Palestinian Authority's security forces, be charged with security in the Gaza Strip, once the war is over. | F38: =VLOOKUP($A38,Hebrew!$A:$S,4,0) -> כחלק מהדיונים על מה שמכונה "היום שאחרי" בעזה, פקידים אמריקאים, ערבים וישראלים הציעו שמוחמד דחלאן, שהיה בעבר ראש כוחות הביטחון של הרשות הפלסטינית וחי כיום באבו דאבי, ימונה לאחראי על הביטחון ברצועת עזה, לאחר שהמלחמה תסתיים. | G38: July 25, 2024 | J38: The Wall Street Journal | K38: Summer Said, Fatima AbdulKarim, and Stephen Kalin | L38: =VLOOKUP($A38,Hebrew!$A:$S,9,0) -> סאמר סייד, פאטימה עבדולכרים, וסטיבן קלין | O38: English | Q38: =VLOOKUP($A38,Hebrew!$A:$S,13,0) -> רצועת עזה | R38: Journalistic report | S38: Text | U38: Hamas, United States
A39: 2421 | B39: https://time.com/7008717/benjamin-netanyahu-interview/ | C39: Bibi at war: Benjamin Netanyahu on Israel's historic crisis and his own | D39: =VLOOKUP(A39,Hebrew!A:C,3,0) -> ביבי במלחמה: בנימין נתניהו על המשבר ההיסטורי של ישראל ועל מדיניתו | E39: Benjamin Netanyahu's leadership during a time of conflict and criticism, with a focus on Israel's security challenges and international relations. | F39: =VLOOKUP($A39,Hebrew!$A:$S,4,0) -> הנהגת בנימין נתניהו בתקופה של סכסוך וביקורת, עם דגש על אתגרי הביטחון של ישראל ויחסים בינלאומיים. | G39: August 8, 2024 | J39: Time | K39: Eric Cortellessa | L39: =VLOOKUP($A39,Hebrew!$A:$S,9,0) -> אריק קורטלסה | O39: English | Q39: =VLOOKUP($A39,Hebrew!$A:$S,13,0) -> 0 | R39: Journalistic report | S39: Text | T39: Israeli Society, Hostages, Ground Operation, Ceasefire, Protest (International), Protest (Israel) | U39: Hamas, IDF (Israel Defense Forces) | W39: Benjamin Netanyahu, Antony Blinken
A40: 2422 | B40: https://www.theatlantic.com/international/archive/2024/09/israel-gaza-war-biden-netanyahu-peace-negotiations/679581/ | C40: Inside the year-long American effort to release the hostages, end the fighting in Gaza, and bring peace to the Middle East | D40: =VLOOKUP(A40,Hebrew!A:C,3,0) -> שנה של מאמץ אמריקאי לשחרר את בני הערובה, לסיים את הלחימה בעזה ולהביא שלום למזרח התיכון | E40: The article discusses the American effort to broker peace in the Middle East, focusing on the Biden administration's involvement during a conflict between Israel and Hamas. | F40: =VLOOKUP($A40,Hebrew!$A:$S,4,0) -> המאמר מספק תיאור כרונולוגי של המאמצים האמריקאיים לתווך שלום במזרח התיכון, תוך התמקדות במעורבות של ממשלת ביידן במהלך הסכסוך בין ישראל לחמאס. | G40: September 25, 2024 | J40: The Atlantic | K40: Franklin Foer | L40: =VLOOKUP($A40,Hebrew!$A:$S,9,0) -> פרנקלין פויר | O40: English | P40: North Gaza | Q40: =VLOOKUP($A40,Hebrew!$A:$S,13,0) -> צפון רצועת עזה | R40: Journalistic report | S40: Text | T40: Hostages, Iron Dome, Air Strike | U40: IDF (Israel Defense Forces) | V40: North Gaza | W40: Benny Gantz, Benjamin Netanyahu, Antony Blinken, Joe Biden, Yoav Gallant, Hassan Nasrallah, Yahya Al-Sinwar, Mohammed bin Salman Al Saud
...

Sheet For_Fine_Tune
A1: Number | B1: Link | C1: Title | D1: Title (Hebrew) | E1: Description | F1: Description (Hebrew) | G1: published Date | H1: Event date from | I1: Event date to | J1: Platform | K1: Author | L1: Author (Hebrew) | M1: Source | N1: Reference | O1: Language | P1: Location | Q1: Location (Hebrew) | R1: Type | S1: Media | T1: Theme (tag) | U1: Places & Organizations (tag) | V1: Locations (tag) | W1: Figures (tag)
A2: 2384 | B2: https://www.undp.org/press-releases/new-un-report-impacts-war-have-set-back-development-gaza-much-69-years | C2: UNDP Report says development in Gaza went back by 69 years | D2: דו"ח חדש של UNDP אומר שחלה נסיגה של כ-69 שנים בהתפתחות עזה | E2: A new UN report highlights the severe impacts of war on Gaza's development, projecting a rise in poverty and a significant contraction in GDP and employment in the State of Palestine. | F2: דו"ח חדש מטעם ארגון הפיתוח של האו"ם קובעת שבלי הסרת המגבלות הכלכליות ואפשרות שיקום והשקעות בפיתוח, צפויה עלייה בעוני, צמצום בתמ"ג וברמת התעסוקה בכלכלה הפלסטינית | G2: October 22, 2024 | J2: UNDP (UN Development Programme) | K2: United Nations Development Programme | L2: תכנית הפיתוח של האו"ם (UNPD) | N2: https://www.undp.org/arab-states/publications/gaza-war-expected-socio-economic-impacts-state-palestine-october-2024 | O2: English | P2: Gaza Strip | Q2: רצועת עזה | R2: Official Report | S2: Text | T2: Economy, Humanitarian Aid, Blockade, Reconstruction | V2: Gaza Strip
A3: 2385 | B3: https://www.haaretz.co.il/opinions/2024-12-22/ty-article-opinion/.premium/00000193-ea47-d35c-a79f-fae7bf390000 | C3: Brigadier General Vach's Worldview is Known. Nonetheless, He was Charged with Commanding a Sensitive Area | D3: השקפת העולם של תא"ל ואך ידועה. למרות זאת הופקד על גזרה רגישה בעזה | E3: The opinion piece discusses the military actions in Gaza and the controversial decisions made by Brigadier General Yehuda Vach, despite the sensitivity of the situation. | F3: מאמר הדעה דן בפעילות הצבא ברצועת עזה וחילוקי הדעות סביב החלטות תא"ל וואך, למרות רגישות המצב | G3: December 22, 2024 | H3: August 7, 2024 | J3: Haaretz | K3: Yagil Levi | L3: יגיל לוי | N3: https://www.haaretz.co.il/news/magazine/2024-12-18/ty-article-magazine/.premium/00000193-d01a-dcf9-afbb-deff388f0000 | O3: Hebrew | P3: Netzarim Corridor | Q3: מסדרון נצרים | R3: Opinion | S3: Text | T3: Ethnic Cleansing, Rules of Engagement, Religious Right | U3: IDF (Israel Defense Forces) | V3: Netzarim Corridor
A4: 2386 | B4: https://reliefweb.int/report/occupied-palestinian-territory/israels-assault-foundations-international-law-must-have-consequences-un-experts | C4: UN: Israel must have consequnces for attacking humanitarian law | D4: האו"ם: על ישראל לשאת בשלכות של הפרת הדין הבינלאומי | E4: UN experts condemn Israel's violations of international law in the occupied Palestinian territory and call for accountability for crimes against humanity and war crimes. | F4: מומחי האו"ם מאשימים את ישראל בהפרת החוק הבינלאומי בשטחים הפלסטינים הכבושים וקוראים להכרה בפשעים נגד האנושות ופשעי מלחמה. | G4: December 30, 2024 | J4: ReliefWeb | K4: ReliefWeb | L4: ReliefWeb | N4: https://www.ohchr.org/en/press-releases/2024/12/israels-assault-foundations-international-law-must-have-consequences-un?sub-site=HRC | O4: English | P4: Gaza Strip | Q4: רצועת עזה | R4: Official Report | S4: Text | T4: Murder, Torture, Forced Displacement, Sexual Violence | V4: Kamal Adwan Hospital
A5: 2387 | B5: https://www.idi.org.il/articles/57946 | C5: Poll - 57.5% of Israeli Public Support Complete Hostage Deal in Return for End of War (Jan 2025) | D5: סקר דצמבר 2024: רוב הציבור (57.5%) תומך בעסקה כוללת לשחרור כול החטופים בתמורה לסיום המלחמה | E5: A survey conducted in December 2024 by the Israeli Democracy Institute shows public support for a comprehensive deal to release all captives in exchange for ending the war, with varying opinions across political spectrums. | F5: סקר שערך מכון הישראלי לדמוקרטיה מצא, בין שאר הנושאים, רוב גדול התומך בעסקה כוללת לשחרור החטיפים בתמורה לסיום המלחמה. | G5: January 15, 2025 | H5: 45658 | I5: January 8, 2025 | J5: The Israel Democracy Institute | K5: Prof. Tamar Herman, Dr. Lior Yohanani, Yaron Kaplan, Inna Orly Sapojnikov | L5: פרופ' תמר הרמן, ד"ר ליאור יוחנני, ירון קפלן, אינה אורלי ספוז'ניקוב | N5: https://dataisrael.idi.org.il | O5: Hebrew | P5: Israel | Q5: ישראל | R5: Analysis | S5: Text | T5: Hostage Deal, Ceasefire, Public Opinion, Israeli Society | U5: IDF (Israel Defense Forces) | V5: Israel
A6: 2388 | B6: https://www.mekomit.co.il/%d7%9c%d7%94%d7%a8%d7%95%d7%a1-%d7%90%d7%aa-%d7%94%d7%a9%d7%9c%d7%99%d7%97-%d7%9b%d7%9a-%d7%94%d7%97%d7%a8%d7%99%d7%91%d7%94-%d7%99%d7%a9%d7%a8%d7%90%d7%9c-%d7%90%d7%aa-%d7%9e%d7%aa%d7%a7%d7%a0%d7%99/ | C6: Israel's destruction of journalistic infrastructure in Gaza | D6: להרוס את השליח: כך החריבה ישראל את מתקני העיתונות בעזה | E6: Israel's destruction of media facilities in Gaza, as investigated by Forbidden Stories, highlights the challenges faced by journalists in reporting from the region. | F6: תחקיר של פורבידן סטוריז ושיחה מקומית בעקבות הפגיעה בעיתונאים ובמשרדיהם. | G6: June 26, 2024 | H6: October 7, 2023 | I6: June 25, 2024 | J6: Mekomit | K6: Léa Peruchon | L6: לאה פרושון | O6: Hebrew | P6: Gaza City | Q6: עיר עזה | R6: Journalistic report | S6: Text | T6: Media, Civilians, Air Strike, Rules of Engagement, Journalists, War Crimes | V6: Gaza City
A7: 2389 | B7: https://www.haaretz.co.il/news/magazine/2024-06-25/ty-article-magazine/.premium/00000190-4ac5-da42-a1ba-7fef27c50000 | C7: IDF reserve soldiers refusing to serve further tell their stories | D7: שלושה חיילי מילואים מספרים מדוע יסרבו לשרת בעזה גם אם ישלמו על כך | E7: Three reserve soldiers explain why they will refuse to serve in Gaza, even if they will face consequences. | F7: שלושה חיילי מילואים מסבירים מדוע חתמו על מכתב סירוב לשרת בעזה | G7: June 25, 2024 | H7: May 31, 2024 | J7: Haaretz | K7: Liza Rozovsky | L7: ליזה רוזובסקי | O7: Hebrew | P7: Gaza Strip | Q7: רצועת עזה | R7: Journalistic report | S7: Text | T7: War Crimes, Rules of Engagement, Ground Operation, Hostage Deal | U7: IDF (Israel Defense Forces) | V7: Gaza Strip
A8: 2390 | B8: https://zeteo.com/p/the-myth-of-human-shields-israel-gaza | C8: The Myth of Gaza's civilian population serving as human shields for Hamas | D8: המיתוס של 'מגינים אנושיים' | E8: The article debunks the 'human shields' claim used by Israel in Gaza conflicts, highlighting the impact on civilians and the misuse of the term by the Israeli military. | F8: המאמר חושף את השימוש לראה בטיעון 'מגינים אנושיים' בו משתמש הצבא הישראלי ברצועת עזה, וחושף את השפעתו על האוכלוסייה האזרחית | G8: September 30, 2024 | J8: Zeteo | K8: Muhammad Shehada | L8: מוחמד שחאדה | O8: English | P8: Gaza Strip | Q8: רצועת עזה | R8: Opinion | S8: Text | T8: Civilians, Rules of Engagement, Air Strike, Collective Punishment | V8: Gaza Strip
A9: 2391 | B9: https://www.gazahealthcareletters.org/usa-letter-oct-2-2024 | C9: Letter to US President Biden and Vice President Harris from 99 American physicians who volunteered in Gaza | D9: מכתב 99 רופאים שהתנדבו לשרת בעזה לנשיא ארה"ב ביידן ולסגניתו האריס | E9: American medical professionals who served in Gaza write an open letter to President Biden and Vice President Harris, urging for immediate action to prevent further catastrophe in Gaza and Israel. | F9: במכתב פתוח לנשיא ארה"ב ביידן ולסגניתו האריס פונים אנשי צוותי רפואה אמריקנים לפעול בדחיות למנוע המשך הקטקסטרופה בעזה ובישראל. | G9: October 2, 2024 | H9: October 7, 2023 | I9: 45566 | J9: Gaza Healthcare Letters | K9: American Medical Professionals who Served in Gaza | L9: צוותי רפואה אמריקנים שפעלו בעזה | O9: English | P9: Gaza Strip | Q9: רצועת עזה | R9: Open letter | S9: Text | T9: Civilians, Hospital, Public Health, Torture | U9: United States | V9: Gaza Strip | W9: Joe Biden, Kamala Harris
A10: 2392 | B10: https://www.haaretz.co.il/news/politics/2024-10-30/ty-article-magazine/.premium/00000192-de9d-d7b5-af97-ff9d2d0d0000 | C10: 100 dead in IDF attempt to kill a spotter | D10: איך אפשר להפציץ בניין על כל יושביו?: בבית לאהיא מחפשים ניצולים במבנה שקרס | E10: Residents and rescue workers search for survivors in a collapsed five-story building in Beit Lahia, northern Gaza Strip, following an explosion that occurred the previous morning. | F10: לפי הרשויות בעזה, כמאה בני אדם נהרגו ועוד עשרות נעדרים בתקיפת מבנה מגורים בן חמש קומות בבית לאהיא שאיכלס כ-200 איש. בצה"ל אומרים כי תצפיתן שהה על גג המבנה. אנשי שירותי ההצלה, המשיכו לנסות ולאתר ניצולים. | G10: October 30, 2024 | H10: October 29, 2024 | I10: October 29, 2024 | J10: Haaretz | K10: Jack Khoury | L10: ג'קי חורי | O10: Hebrew | P10: Beit Lahia | Q10: בית לאהיא | R10: Journalistic report | S10: Text | T10: Air Strike, Civilians | V10: Beit Lahiya
A11: 2393 | B11: https://www.theguardian.com/world/article/2024/jul/19/israel-gaza-war-polio-sewage-samples | C11: Polio virus found in Gaza sewage | D11: וירוס פוליו מדבק התגלה בדגימות ביוב בעזה | E11: Highly infectious poliovirus found in Gaza sewage samples, putting thousands at risk of contracting the disease due to poor sanitation and infrastructure conditions. | F11: וירוס פוליו מדבק התגלה בדגימות ביוב בעזה ומעמיד בסכנה אלפי תושבים בגלל תנאי היגיינה ותשתיות פגועים. | G11: July 19, 2024 | J11: The Guardian | K11: Agence France-Presse | L11: סוכנות הידיעות הצרפתית | O11: English | P11: Gaza Strip | Q11: רצועת עזה | R11: Journalistic report | S11: Text | T11: Water, Public Health | V11: Central Gaza Strip
A12: 2394 | B12: https://www.thenationalnews.com/news/mena/2024/06/21/israel-gaza-city-municipality-garage/ | C12: Israel killed water/environment engineer & municipality officials working to restore water supply in Gaza | D12: בתקיפה אווירית נהרגו מהנדסי מים ותשתיות נציגי העירייה שפעלו להחזיר לפעולה את אספקת המים | E12: An Israeli airstrike on a Gaza City municipal building kills at least five workers, including four preparing to restore drinking water wells, leading to significant destruction and impacting essential services in the war-torn enclave. | F12: בתקיפה אווירית ישראלית על בנין העירייה של עזה נהרגו לפחות ארבעה שעבדו על חידוש אספקת מים לבארות המים ובכך פגעו אנושות באספקת משאב חיוני בעזה הנצורה. | G12: June 21, 2024 | H12: June 21, 2024 | I12: June 21, 2024 | J12: The National | K12: Nagham Mohanna | L12: נאגהם מוחאנה | O12: English | P12: Gaza City | Q12: עיר עזה | R12: Journalistic report | S12: Text | T12: Air Strike, Civilians, Water | V12: Gaza City
A13: 2395 | B13: https://www.globaltimes.cn/page/202411/1322528.shtml | C13: Gazans boycott local markets due to exhorbitant food prices | D13: עזתים מחרימים שווקים מקומיים בשל הפקעת מחירים | E13: Markets in Gaza are empty as locals boycott due to soaring prices amid the conflict with Israel, leading to protests and accusations of price manipulation by traders. | F13: שווקים בעזה התרוקנו בשל חרם של העזתים במחאה על האשמת הסוחרים מחירים המופקעים | G13: November 6, 2024 | H13: November 5, 2024 | J13: Global Times | K13: Xinhua | L13: סוכנות הידיעות הסינית | O13: English | P13: Central Gaza; Southern Gaza | Q13: מרכז ודרום רצועת עזה | R13: Journalistic report | S13: Text | T13: Food, Humanitarian Aid | V13: Gaza Strip
A14: 2396 | B14: https://amp.cnn.com/cnn/2024/11/29/middleeast/gaza-bakery-crush-palestinians-killed-intl-latam | C14: 3 Palestinians crushed to death in line to get food | D14: בתור לאוכל נמחצו למוות אישה ושני ילדים פלסטינים | E14: Three Palestinians, including two children and a woman, were crushed to death outside a bakery in Gaza amid a worsening food crisis in the enclave. | F14: על רקע מצוקת המזון הגוברת ברצונת עזה נמחצו למוות אישה ושני ילדים פלסטינים בתור למאפיה. | G14: November 30 ,2024 | H14: November 29, 2024 | I14: November 29, 2024 | J14: CNN | K14: Abeer Salman; Mohammad Al Sawalhi; Ibrahim Dahman; Mitchell McCluskey | L14: אביר סלמאן, מוחמד אל-סוואלי, איברהים דמאן, מישל מק'לאסקי | O14: English | P14: Central Gaza | Q14: מרכז רצועת עזה | R14: Journalistic report | S14: Text | T14: Humanitarian Aid, Food, Civilians | V14: Central Gaza Strip
A15: 2397 | B15: https://thebaffler.com/latest/running-amok-turfah | C15: Dehumanizing social media posts by Israeli soldiers in Gaza | D15: דהומנציזציה של הפלסטינים מוצגת על ידי חיילים ישראלים בסרטונים במדיה החברתית | E15: The content discusses various disturbing behaviors exhibited by Israeli soldiers in Gaza, including destruction, looting, and disrespectful actions towards Palestinians. | F15: בסרטונים תכנים מטרידים של חיילי ישראל, כולל תיאורי הרס, ביזה והתנהגות לא מכובדת כלפי פלסטינים | G15: June 18, 2024 | J15: The Baffler | K15: Mary Turfah | L15: מרי טורפה | O15: English | P15: Gaza Strip | Q15: רצועת עזה | R15: Journalistic report | S15: Text | T15: Vandalism | U15: IDF (Israel Defense Forces) | V15: Gaza Strip
A16: 2398 | B16: https://www.haaretz.com/israel-news/2024-09-03/ty-article/.premium/israeli-army-reservists-assault-gazan-truck-drivers-working-for-aid-organizations/00000191-b71d-d13c-a39b-bf9d24710000 | C16: Israeli army reservist assault Gazan truck drivers working for aid organizations | D16: חיילי מילואים תוקפים נהגי משאיות עזתים העובדים עבור ארגוני סיוע | E16: Israeli army reservists assaulted Gazan truck drivers working for aid organizations, despite being cleared by Israel's security services. | F16: חיילי מילואים תוקפים נהגי משאיות עזתים העובדים עבור ארגוני סיוע למרות שיש להם אישור מכוחות הביטחון | G16: September 3, 2024 | H16: 45505 | J16: Haaretz | K16: Yaniv Kubovich | L16: יניב קובוביץ | O16: English | P16: Kerem Shalom Crossing | Q16: מעבר כרם שלום | R16: Journalistic report | S16: Text | T16: Humanitarian Aid, Civilians | U16: IDF (Israel Defense Forces) | V16: Kerem Shalom Crossing
A17: 2399 | B17: https://www.themarker.com/news/education/2024-09-30/ty-article/00000192-41e6-d07b-aff3-57e6401a0000 | C17: Israeli Ministry of Education Directorate of Religious Education calls for schools to celebrate killing of Hezbollah leader Hassan Nasrallah | D17: משרד החינוך קרא לבתי הספר לערוך הרקדות ומשלוחי מנות לתלמידים עקב חיסול נסראללה | E17: The Ministry of Education instructed religious state schools to hold dances and send food packages to students following the killing of Hezbollah leader Hassan Nasrallah, sparking debates within the religious community. | F17: מינהל החינוך הדתי במשרד החינוך, האחראי על הפיקוח על רבני בתי הספר הממלכתיים־דתיים, הנחה בתי ספר לערוך חגיגות לציון הרג מנהיג חיזבאללה. היו גורמים במשרד שמתחו ביקורת על המהלך | G17: September 30, 2024 | H17: September 29, 2024 | I17: September 29, 2024 | J17: The Marker | K17: Lior Dattel | L17: ליאור דטל | O17: Hebrew | P17: Israel | Q17: ישראל | R17: Journalistic report | S17: Text | T17: Israeli Society | V17: Israel | W17: Hassan Nasrallah
A18: 2400 | B18: https://www.haaretz.co.il/news/law/2024-09-23/ty-article/.premium/00000192-1b6b-d342-ab9f-df6b2b790000 | C18: Deputy Mayor of Jerusalem interrogated under suspicion of inciting to violence and terrorism | D18: סגן ראש העיר ירושלים נחקר בחשד להסתה לטרור לאחר שפרסם פוסטים נגד אונר"א | E18: Jerusalem's Deputy Mayor, Aryeh King, is under investigation for incitement to violence and terrorism after posting against the UN - Law and Crime | F18: סגן ראש העיר ירושלים נחקר בחשד להסתה לאלימות והסתה לטרור לאחר שפרסם פוסטים נגד אונר"א ועידוד לשריפת מבני אונר"א | G18: September 23, 2024 | H18: September 23, 2024 | J18: Haaretz | K18: Yael Freidson | L18: יעל פרידסון | O18: Hebrew | P18: Israel | Q18: ישראל | R18: Journalistic report | S18: Text | T18: Terrorism | U18: Israeli Police, UNRWA (The UN Relief and Works Agency for Palestine Refugees) | V18: Jerusalem
A19: 2401 | B19: https://www.nytimes.com/2024/10/14/world/middleeast/israel-gaza-military-human-shields.html | C19: Israeli Army uses Palestinian civilians as human shields in Gaza | D19: צה"ל משתמש באזרחים פלסטינים כמגינים חיים בעזה. | E19: Israeli soldiers have been accused of using Palestinians as human shields in Gaza, forcing them to carry out dangerous tasks, as reported by The New York Times. | F19: חיילי צה"ל לפי דיווח בניו יורק טיימס מאלצים אזרחים פלסטינים לשמש כמגינים חיים ולבצע משימות מסכנות חיים. | G19: October 14, 2024 | J19: The New York Times | K19: Natan Odenheimer; Bilal Shbair; Patrick Kingsley | L19: נתן אודנהיימר, בילאל שבאר, פטריק קינגסלי | O19: English | P19: Gaza Strip | Q19: רצועת עזה | R19: Journalistic report | S19: Text | T19: Ground Operation, Civilians | U19: IDF (Israel Defense Forces) | V19: Gaza Strip
A20: 2402 | B20: https://www.haaretz.co.il/news/magazine/2024-06-28/ty-article-magazine/.premium/00000190-5aa7-de5e-abd0-fbf704260000 | C20: A night with an IDF ghost unit that has been fighting in the Gaza Strip for eight months | D20: לילה עם יחידת רפאים של צה"ל, שנלחמת ברצועה כבר שמונה חודשים | E20: An article about a night with the IDF's Re'phaim unit, which has been fighting in the Gaza Strip for eight months. | F20: לילה עם יחידת רפאים של צה"ל, שמכונה גם היחידה הרב-ממדית, שתפקידה לאתר ולפגוע במחבלים בעומק שטח הלחימה באמצעות יכולות טכנולוגיות מתקדמות | G20: June 28,2024 | H20: June 21, 2024 | J20: Haaretz | K20: Yaniv Kubovich | L20: יניב קובוביץ | O20: Hebrew | P20: Gaza Strip | Q20: רצועת עזה | R20: Journalistic report | S20: Text | T20: Hostages | U20: IDF (Israel Defense Forces) | V20: Gaza Strip
A21: 2403 | B21: https://www.haaretz.co.il/news/politics/2024-10-16/ty-article/.premium/00000192-94aa-d9c2-a7f3-9cae337a0000 | C21: An invitation from Likud for an event in the Gaza border area was distributed under the title 'Preparing to settle in the Gaza region | D21: הזמנה מטעם הליכוד לאירוע בעוטף הופצה תחת הכותרת "נערכים להתיישב בחבל עזה" | E21: The Likud party has issued an invitation for an event in the Gaza envelope titled 'Preparing to settle in the Gaza Strip' with the participation of several Likud Knesset members. | F21: לפי ההזמנה, הליכוד יקים סוכה כחלק מ"עיר סוכות" בעוטף עזה של תנועת "נחלה", שפועלת להקמת מאחזים בלתי חוקיים בגדה. בהזמנה נכתב כי ח"כים מהליכוד צפויים להגיע | G21: October 16,2024 | J21: Haaretz | K21: Noa Spigel | L21: נועה שפיגל | O21: Hebrew | P21: Western Negev (Otef) | Q21: עוטף עזה | R21: Journalistic report | S21: Text | T21: Israeli Society, Settlements | V21: Western Negev (Otef) | W21: Benny Gantz, Benjamin Netanyahu
